Workbook
Name _ReviewStatus: '[1]Catalogue Values (Wertelisten)'!$L$2:$L$3
Name cmbAnswerRequired: #REF!
Name cmbAreaRoom: #REF!
Name cmbBook: #REF!
Name cmbCableTag: #REF!
Name cmbCableTagConductor: #REF!
Name cmbCableTagLineNo: #REF!
Name cmbContractLot: #REF!
Name cmbContractLot2: #REF!
Name cmbDataType: '[2]Catalogue Values (Wertelisten)'!$J$2:$J$3
Name cmbDCCA2A3nnnSubClass: #REF!
Name cmbDCCA2A3SubClass: #REF!
Name cmbDCCA2MainClass: #REF!
Name cmbDccIdentityNumber: #REF!
Name cmbDccMainClass: #REF!
Name cmbDccSubClass: #REF!
Name cmbDestinationContainer: #REF!
Name cmbDiscipline: #REF!
Name cmbEmployersQcStatus: #REF!
Name cmbFinalAsBuilt: '[2]Catalogue Values (Wertelisten)'!$V$2:$V$2
Name cmbForHandover: #REF!
Name cmbGrantAccessTo: #REF!
Name cmbIsInterfaceDocument: '[3]Catalogue Values (Wertelisten)'!$CP$2:$CP$3
Name cmbItemDesignationComplete: #REF!
Name cmbKmPoints: #REF!
Name cmbLanguage: '[2]Catalogue Values (Wertelisten)'!$L$2:$L$3
Name cmbLocation: #REF!
Name cmbObjectClassSIE: '[2]Catalogue Values (Wertelisten)'!$AN$2:$AN$4
Name cmbOriginatingCompany: '[2]Catalogue Values (Wertelisten)'!$H$2:$H$7
Name cmbPaymentMilestone: #REF!
Name cmbPermitStructure: #REF!
Name cmbPhase: #REF!
Name cmbProjectMainGroup: #REF!
Name cmbProjectSubGroup: #REF!
Name cmbPurposeOfIssue: #REF!
Name cmbPurposeOfSubmission: '[2]Catalogue Values (Wertelisten)'!$P$2:$P$4
Name cmbReceivingCompany: #REF!
Name cmbRev: '[2]Catalogue Values (Wertelisten)'!$F$2:$F$102
Name cmbReviewStatus: '[2]Catalogue Values (Wertelisten)'!$R$2:$R$3
Name cmbSendingCompany: #REF!
Name cmbSheetNumber: #REF!
Name cmbShowColumns: #REF!
Name cmbSize: #REF!
Name cmbStatusCertifier: '[2]Catalogue Values (Wertelisten)'!$T$2:$T$10
Name cmbTagBL1: #REF!
Name cmbTagBL2: #REF!
Name cmbTagBL3: #REF!
Name cmbTagBL4: #REF!
Name cmbTagBL5: #REF!
Name cmbToBeForwardedTo: #REF!
Name cmbTogStructureBook: #REF!
Name cmbTogStructureChapter: #REF!
Name cmbTogStructureSection: #REF!
Name cmbTypical: '[2]Catalogue Values (Wertelisten)'!$AP$2:$AP$3
Name cmbUsers: #REF!
Name cmbVDLocationDiscipline: #REF!
Name cmbVDLocationPurposeOfIssue: #REF!
Name cmbWbsPackage: '[2]Catalogue Values (Wertelisten)'!$AB$2:$AB$240
Name cmbWindFarm: #REF!
Name fechas: #REF!

Sheet Drawing List TWP
G1: Yuil Detailed Fabrication Drawing List for Pannels - Upper Grillage
C3: Priority | D3: Contractor Dwg.-ID: | E3: BA21-OS-TOPS-CF-YU1002-EN | F3: Project
C4: Priority | D4: Employer Dwg.-ID: | E4: #BAL.BA21=212&AB010-000010 | F4: Balwin 2 | P4: DOSA REVISION HISTORY | V4: Document revision/approval stage
D5: YUIL SHOP DRAWING NUMBER (Internal Use) | E5: Contractor Dwg.-ID: (Include in drawing box) | F5: Employer Dwg.-ID: (Include in drawing box) | G5: DRAWING TITLE | I5: STR.CAT | J5: BLOCK | K5: LOC (where) | L5: TYPE (what) | M5: STAGE (who) | N5: DESIGN DRWG | O5: DESIGN DRAWING | P5: R01 | R5: R02 | T5: R03 | V5: DWG Rev | W5: Current STATUS | X5: DWG Transmittals/ Approval INFO | Y5: DATE
A6: NO.1 | B6: NO.2 | H6: dead line submiss | P6: Date | Q6: Status | R6: *Expected Date of submission | S6: Status | AB6: Submitted | AC6: Code 1 | AD6: Code 2 | AE6: Code 3
A7: 1 | B7: 1 | C7: I | D7: BA21-OS-TOPS-ST-601100-EN | E7: BA21-OS-TOPS-ST-706401-EN | F7: #BAL.BA21=212&TC030-706401-EN | G7: Topside - Upper Grillage - Pri. Steel -Block A1,A2 Nesting Plan | H7: 47359 | I7: PRI. STEEL | J7: A1,A2 | K7: Deck & Section | L7: NESTING PLAN | M7: PREFAB | N7: BA11-OS-TOPS-ST-300214-EN | O7: Topside Upper Grillage Arrangement | P7: 45898 | Q7: Submitted | R7: 45910 | V7: R1 | W7: Submitted | X7: Sent in TR_DRW_GRI_BA2_DOSA_001 | Y7: 45898
A8: 2 | B8: 2 | C8: I | D8: BA21-OS-TOPS-ST-600101-EN | E8: BA21-OS-TOPS-ST-706406-EN | F8: #BAL.BA21=212&TC030-706406-EN | G8: Topside - Upper Grillage - Pri. Steel -Block A1 Sub Assembly SA01 | H8: 47359 | I8: PRI. STEEL | J8: A1 | K8: Deck & Section | L8: FABRICATION | M8: PREFAB | N8: BA11-OS-TOPS-ST-300214-EN | O8: Topside Upper Grillage Arrangement | P8: 45898 | Q8: Submitted | R8: 45910 | V8: R1 | W8: Submitted | X8: Sent in TR_DRW_GRI_BA2_DOSA_001 | Y8: 45898
B9: 2 | C9: I | D9: BA21-OS-TOPS-ST-600101-001-EN | E9: BA21-OS-TOPS-ST-706406-001-EN | F9: #BAL.BA21=212&TC030-706406-001-EN | G9: Topside - Upper Grillage - Pri. Steel -Block A1 Sub Assembly SA01_Sheet.001 | H9: 47359 | I9: PRI. STEEL | J9: A1 | K9: Deck & Section | L9: FABRICATION | M9: PREFAB | N9: BA11-OS-TOPS-ST-300214-EN | O9: Topside Upper Grillage Arrangement | P9: 45898 | Q9: Submitted | R9: 45910 | V9: R1 | X9: Sent in TR_DRW_GRI_BA2_DOSA_001 | Y9: 45898
B10: 3 | D10: BA21-OS-TOPS-ST-600101-002-EN | E10: BA21-OS-TOPS-ST-706406-002-EN | F10: #BAL.BA21=212&TC030-706406-002-EN | G10: Topside - Upper Grillage - Pri. Steel -Block A1 Sub Assembly SA01_Sheet.002 | H10: 47359 | I10: PRI. STEEL | J10: A1 | K10: Deck & Section | L10: FABRICATION | M10: PREFAB | N10: BA11-OS-TOPS-ST-300214-EN | O10: Topside Upper Grillage Arrangement | P10: 45898 | Q10: Submitted | R10: 45910 | V10: R1 | X10: Sent in TR_DRW_GRI_BA2_DOSA_001 | Y10: 45898
B11: 4 | D11: BA21-OS-TOPS-ST-600101-003-EN | E11: BA21-OS-TOPS-ST-706406-003-EN | F11: #BAL.BA21=212&TC030-706406-003-EN | G11: Topside - Upper Grillage - Pri. Steel -Block A1 Sub Assembly SA01_Sheet.003 | H11: 47359 | I11: PRI. STEEL | J11: A1 | K11: Deck & Section | L11: FABRICATION | M11: PREFAB | N11: BA11-OS-TOPS-ST-300214-EN | O11: Topside Upper Grillage Arrangement | P11: 45898 | Q11: Submitted | R11: 45910 | V11: R1 | X11: Sent in TR_DRW_GRI_BA2_DOSA_001 | Y11: 45898
A12: 3 | B12: 5 | C12: I | D12: BA21-OS-TOPS-ST-600102-EN | E12: BA21-OS-TOPS-ST-706407-EN | F12: #BAL.BA21=212&TC030-706407-EN | G12: Topside - Upper Grillage - Pri. Steel -Block A1 Sub Assembly SA02 | H12: 47359 | I12: PRI. STEEL | J12: A1 | K12: Deck & Section | L12: FABRICATION | M12: PREFAB | N12: BA11-OS-TOPS-ST-300214-EN | O12: Topside Upper Grillage Arrangement | P12: 45898 | Q12: Submitted | R12: 45910 | V12: R1 | W12: Submitted | X12: Sent in TR_DRW_GRI_BA2_DOSA_001 | Y12: 45898
B13: 5 | C13: I | D13: BA21-OS-TOPS-ST-600102-001-EN | E13: BA21-OS-TOPS-ST-706407-001-EN | F13: #BAL.BA21=212&TC030-706407-001-EN | G13: Topside - Upper Grillage - Pri. Steel -Block A1 Sub Assembly SA02_Sheet.001 | H13: 47359 | I13: PRI. STEEL | J13: A1 | K13: Deck & Section | L13: FABRICATION | M13: PREFAB | N13: BA11-OS-TOPS-ST-300214-EN | O13: Topside Upper Grillage Arrangement | P13: 45898 | Q13: Submitted | R13: 45910 | V13: R1 | X13: Sent in TR_DRW_GRI_BA2_DOSA_001 | Y13: 45898
B14: 6 | C14: I | D14: BA21-OS-TOPS-ST-600102-002-EN | E14: BA21-OS-TOPS-ST-706407-002-EN | F14: #BAL.BA21=212&TC030-706407-002-EN | G14: Topside - Upper Grillage - Pri. Steel -Block A1 Sub Assembly SA02_Sheet.002 | H14: 47359 | I14: PRI. STEEL | J14: A1 | K14: Deck & Section | L14: FABRICATION | M14: PREFAB | N14: BA11-OS-TOPS-ST-300214-EN | O14: Topside Upper Grillage Arrangement | P14: 45898 | Q14: Submitted | R14: 45910 | V14: R1 | X14: Sent in TR_DRW_GRI_BA2_DOSA_001 | Y14: 45898
B15: 7 | C15: I | D15: BA21-OS-TOPS-ST-600102-003-EN | E15: BA21-OS-TOPS-ST-706407-003-EN | F15: #BAL.BA21=212&TC030-706407-003-EN | G15: Topside - Upper Grillage - Pri. Steel -Block A1 Sub Assembly SA02_Sheet.003 | H15: 47359 | I15: PRI. STEEL | J15: A1 | K15: Deck & Section | L15: FABRICATION | M15: PREFAB | N15: BA11-OS-TOPS-ST-300214-EN | O15: Topside Upper Grillage Arrangement | P15: 45898 | Q15: Submitted | R15: 45910 | V15: R1 | X15: Sent in TR_DRW_GRI_BA2_DOSA_001 | Y15: 45898
B16: 8 | C16: I | D16: BA21-OS-TOPS-ST-600102-004-EN | E16: BA21-OS-TOPS-ST-706407-004-EN | F16: #BAL.BA21=212&TC030-706407-004-EN | G16: Topside - Upper Grillage - Pri. Steel -Block A1 Sub Assembly SA02_Sheet.004 | H16: 47359 | I16: PRI. STEEL | J16: A1 | K16: Deck & Section | L16: FABRICATION | M16: PREFAB | N16: BA11-OS-TOPS-ST-300214-EN | O16: Topside Upper Grillage Arrangement | P16: 45898 | Q16: Submitted | R16: 45910 | V16: R1 | X16: Sent in TR_DRW_GRI_BA2_DOSA_001 | Y16: 45898
B17: 9 | C17: I | D17: BA21-OS-TOPS-ST-600102-005-EN | E17: BA21-OS-TOPS-ST-706407-005-EN | F17: #BAL.BA21=212&TC030-706407-005-EN | G17: Topside - Upper Grillage - Pri. Steel -Block A1 Sub Assembly SA02_Sheet.005 | H17: 47359 | I17: PRI. STEEL | J17: A1 | K17: Deck & Section | L17: FABRICATION | M17: PREFAB | N17: BA11-OS-TOPS-ST-300214-EN | O17: Topside Upper Grillage Arrangement | P17: 45898 | Q17: Submitted | R17: 45910 | V17: R1 | X17: Sent in TR_DRW_GRI_BA2_DOSA_001 | Y17: 45898
A18: 4 | B18: 10 | C18: I | D18: BA21-OS-TOPS-ST-600103-EN | E18: BA21-OS-TOPS-ST-706408-EN | F18: #BAL.BA21=212&TC030-706408-EN | G18: Topside - Upper Grillage - Pri. Steel -Block A1 Sub Assembly SA03 | H18: 47359 | I18: PRI. STEEL | J18: A1 | K18: Deck & Section | L18: FABRICATION | M18: PREFAB | N18: BA11-OS-TOPS-ST-300214-EN | O18: Topside Upper Grillage Arrangement | P18: 45898 | Q18: Submitted | R18: 45910 | V18: R1 | W18: Submitted | X18: Sent in TR_DRW_GRI_BA2_DOSA_001 | Y18: 45898
B19: 10 | C19: I | D19: BA21-OS-TOPS-ST-600103-001-EN | E19: BA21-OS-TOPS-ST-706408-001-EN | F19: #BAL.BA21=212&TC030-706408-001-EN | G19: Topside - Upper Grillage - Pri. Steel -Block A1 Sub Assembly SA03_Sheet.001 | H19: 47359 | I19: PRI. STEEL | J19: A1 | K19: Deck & Section | L19: FABRICATION | M19: PREFAB | N19: BA11-OS-TOPS-ST-300214-EN | O19: Topside Upper Grillage Arrangement | P19: 45898 | Q19: Submitted | R19: 45910 | V19: R1 | X19: Sent in TR_DRW_GRI_BA2_DOSA_001 | Y19: 45898
B20: 11 | C20: I | D20: BA21-OS-TOPS-ST-600103-002-EN | E20: BA21-OS-TOPS-ST-706408-002-EN | F20: #BAL.BA21=212&TC030-706408-002-EN | G20: Topside - Upper Grillage - Pri. Steel -Block A1 Sub Assembly SA03_Sheet.002 | H20: 47359 | I20: PRI. STEEL | J20: A1 | K20: Deck & Section | L20: FABRICATION | M20: PREFAB | N20: BA11-OS-TOPS-ST-300214-EN | O20: Topside Upper Grillage Arrangement | P20: 45898 | Q20: Submitted | R20: 45910 | V20: R1 | X20: Sent in TR_DRW_GRI_BA2_DOSA_001 | Y20: 45898
B21: 12 | C21: I | D21: BA21-OS-TOPS-ST-600103-003-EN | E21: BA21-OS-TOPS-ST-706408-003-EN | F21: #BAL.BA21=212&TC030-706408-003-EN | G21: Topside - Upper Grillage - Pri. Steel -Block A1 Sub Assembly SA03_Sheet.003 | H21: 47359 | I21: PRI. STEEL | J21: A1 | K21: Deck & Section | L21: FABRICATION | M21: PREFAB | N21: BA11-OS-TOPS-ST-300214-EN | O21: Topside Upper Grillage Arrangement | P21: 45898 | Q21: Submitted | R21: 45910 | V21: R1 | X21: Sent in TR_DRW_GRI_BA2_DOSA_001 | Y21: 45898
B22: 13 | C22: I | D22: BA21-OS-TOPS-ST-600103-004-EN | E22: BA21-OS-TOPS-ST-706408-004-EN | F22: #BAL.BA21=212&TC030-706408-004-EN | G22: Topside - Upper Grillage - Pri. Steel -Block A1 Sub Assembly SA03_Sheet.004 | H22: 47359 | I22: PRI. STEEL | J22: A1 | K22: Deck & Section | L22: FABRICATION | M22: PREFAB | N22: BA11-OS-TOPS-ST-300214-EN | O22: Topside Upper Grillage Arrangement | P22: 45898 | Q22: Submitted | R22: 45910 | V22: R1 | X22: Sent in TR_DRW_GRI_BA2_DOSA_001 | Y22: 45898
A23: 5 | B23: 14 | C23: I | D23: BA21-OS-TOPS-ST-600104-EN | E23: BA21-OS-TOPS-ST-706409-EN | F23: #BAL.BA21=212&TC030-706409-EN | G23: Topside - Upper Grillage - Pri. Steel -Block A1 Sub Assembly SA04 | H23: 47359 | I23: PRI. STEEL | J23: A1 | K23: Deck & Section | L23: FABRICATION | M23: PREFAB | N23: BA11-OS-TOPS-ST-300214-EN | O23: Topside Upper Grillage Arrangement | P23: 45898 | Q23: Submitted | R23: 45910 | V23: R1 | W23: Submitted | X23: Sent in TR_DRW_GRI_BA2_DOSA_001 | Y23: 45898
B24: 14 | C24: I | D24: BA21-OS-TOPS-ST-600104-001-EN | E24: BA21-OS-TOPS-ST-706409-001-EN | F24: #BAL.BA21=212&TC030-706409-001-EN | G24: Topside - Upper Grillage - Pri. Steel -Block A1 Sub Assembly SA04_Sheet.001 | H24: 47359 | I24: PRI. STEEL | J24: A1 | K24: Deck & Section | L24: FABRICATION | M24: PREFAB | N24: BA11-OS-TOPS-ST-300214-EN | O24: Topside Upper Grillage Arrangement | P24: 45898 | Q24: Submitted | R24: 45910 | V24: R1 | X24: Sent in TR_DRW_GRI_BA2_DOSA_001 | Y24: 45898
B25: 15 | C25: I | D25: BA21-OS-TOPS-ST-600104-002-EN | E25: BA21-OS-TOPS-ST-706409-002-EN | F25: #BAL.BA21=212&TC030-706409-002-EN | G25: Topside - Upper Grillage - Pri. Steel -Block A1 Sub Assembly SA04_Sheet.002 | H25: 47359 | I25: PRI. STEEL | J25: A1 | K25: Deck & Section | L25: FABRICATION | M25: PREFAB | N25: BA11-OS-TOPS-ST-300214-EN | O25: Topside Upper Grillage Arrangement | P25: 45898 | Q25: Submitted | R25: 45910 | V25: R1 | X25: Sent in TR_DRW_GRI_BA2_DOSA_001 | Y25: 45898
A26: 6 | B26: 16 | C26: I | D26: BA21-OS-TOPS-ST-600105-EN | E26: BA21-OS-TOPS-ST-706410-EN | F26: #BAL.BA21=212&TC030-706410-EN | G26: Topside - Upper Grillage - Pri. Steel -Block A1 Sub Assembly SA05 | H26: 47359 | I26: PRI. STEEL | J26: A1 | K26: Deck & Section | L26: FABRICATION | M26: PREFAB | N26: BA11-OS-TOPS-ST-300214-EN | O26: Topside Upper Grillage Arrangement | P26: 45898 | Q26: Submitted | R26: 45910 | V26: R1 | W26: Submitted | X26: Sent in TR_DRW_GRI_BA2_DOSA_001 | Y26: 45898
B27: 16 | C27: I | D27: BA21-OS-TOPS-ST-600105-001-EN | E27: BA21-OS-TOPS-ST-706410-001-EN | F27: #BAL.BA21=212&TC030-706410-001-EN | G27: Topside - Upper Grillage - Pri. Steel -Block A1 Sub Assembly SA05_Sheet.001 | H27: 47359 | I27: PRI. STEEL | J27: A1 | K27: Deck & Section | L27: FABRICATION | M27: PREFAB | N27: BA11-OS-TOPS-ST-300214-EN | O27: Topside Upper Grillage Arrangement | P27: 45898 | Q27: Submitted | R27: 45910 | V27: R1 | X27: Sent in TR_DRW_GRI_BA2_DOSA_001 | Y27: 45898
B28: 17 | C28: I | D28: BA21-OS-TOPS-ST-600105-002-EN | E28: BA21-OS-TOPS-ST-706410-002-EN | F28: #BAL.BA21=212&TC030-706410-002-EN | G28: Topside - Upper Grillage - Pri. Steel -Block A1 Sub Assembly SA05_Sheet.002 | H28: 47359 | I28: PRI. STEEL | J28: A1 | K28: Deck & Section | L28: FABRICATION | M28: PREFAB | N28: BA11-OS-TOPS-ST-300214-EN | O28: Topside Upper Grillage Arrangement | P28: 45898 | Q28: Submitted | R28: 45910 | V28: R1 | X28: Sent in TR_DRW_GRI_BA2_DOSA_001 | Y28: 45898
B29: 18 | C29: I | D29: BA21-OS-TOPS-ST-600105-003-EN | E29: BA21-OS-TOPS-ST-706410-003-EN | F29: #BAL.BA21=212&TC030-706410-003-EN | G29: Topside - Upper Grillage - Pri. Steel -Block A1 Sub Assembly SA05_Sheet.003 | H29: 47359 | I29: PRI. STEEL | J29: A1 | K29: Deck & Section | L29: FABRICATION | M29: PREFAB | N29: BA11-OS-TOPS-ST-300214-EN | O29: Topside Upper Grillage Arrangement | P29: 45898 | Q29: Submitted | R29: 45910 | V29: R1 | X29: Sent in TR_DRW_GRI_BA2_DOSA_001 | Y29: 45898
B30: 19 | C30: I | D30: BA21-OS-TOPS-ST-600105-004-EN | E30: BA21-OS-TOPS-ST-706410-004-EN | F30: #BAL.BA21=212&TC030-706410-004-EN | G30: Topside - Upper Grillage - Pri. Steel -Block A1 Sub Assembly SA05_Sheet.004 | H30: 47359 | I30: PRI. STEEL | J30: A1 | K30: Deck & Section | L30: FABRICATION | M30: PREFAB | N30: BA11-OS-TOPS-ST-300214-EN | O30: Topside Upper Grillage Arrangement | P30: 45898 | Q30: Submitted | R30: 45910 | V30: R1 | X30: Sent in TR_DRW_GRI_BA2_DOSA_001 | Y30: 45898
A31: 7 | B31: 20 | C31: I | D31: BA21-OS-TOPS-ST-600106-EN | E31: BA21-OS-TOPS-ST-706411-EN | F31: #BAL.BA21=212&TC030-706411-EN | G31: Topside - Upper Grillage - Pri. Steel -Block A1 Sub Assembly SA06 | H31: 47359 | I31: PRI. STEEL | J31: A1 | K31: Deck & Section | L31: FABRICATION | M31: PREFAB | N31: BA11-OS-TOPS-ST-300214-EN | O31: Topside Upper Grillage Arrangement | P31: 45898 | Q31: Submitted | R31: 45910 | V31: R1 | W31: Submitted | X31: Sent in TR_DRW_GRI_BA2_DOSA_001 | Y31: 45898
B32: 20 | C32: I | D32: BA21-OS-TOPS-ST-600106-001-EN | E32: BA21-OS-TOPS-ST-706411-001-EN | F32: #BAL.BA21=212&TC030-706411-001-EN | G32: Topside - Upper Grillage - Pri. Steel -Block A1 Sub Assembly SA06_Sheet.001 | H32: 47359 | I32: PRI. STEEL | J32: A1 | K32: Deck & Section | L32: FABRICATION | M32: PREFAB | N32: BA11-OS-TOPS-ST-300214-EN | O32: Topside Upper Grillage Arrangement | P32: 45898 | Q32: Submitted | R32: 45910 | V32: R1 | X32: Sent in TR_DRW_GRI_BA2_DOSA_001 | Y32: 45898
B33: 21 | C33: I | D33: BA21-OS-TOPS-ST-600106-002-EN | E33: BA21-OS-TOPS-ST-706411-002-EN | F33: #BAL.BA21=212&TC030-706411-002-EN | G33: Topside - Upper Grillage - Pri. Steel -Block A1 Sub Assembly SA06_Sheet.002 | H33: 47359 | I33: PRI. STEEL | J33: A1 | K33: Deck & Section | L33: FABRICATION | M33: PREFAB | N33: BA11-OS-TOPS-ST-300214-EN | O33: Topside Upper Grillage Arrangement | P33: 45898 | Q33: Submitted | R33: 45910 | V33: R1 | X33: Sent in TR_DRW_GRI_BA2_DOSA_001 | Y33: 45898
A34: 8 | B34: 22 | C34: I | D34: BA21-OS-TOPS-ST-600107-EN | E34: BA21-OS-TOPS-ST-706412-EN | F34: #BAL.BA21=212&TC030-706412-EN | G34: Topside - Upper Grillage - Pri. Steel -Block A1 Sub Assembly SA07 | H34: 47359 | I34: PRI. STEEL | J34: A1 | K34: Deck & Section | L34: FABRICATION | M34: PREFAB | N34: BA11-OS-TOPS-ST-300214-EN | O34: Topside Upper Grillage Arrangement | P34: 45898 | Q34: Submitted | R34: 45910 | V34: R1 | W34: Submitted | X34: Sent in TR_DRW_GRI_BA2_DOSA_001 | Y34: 45898
B35: 22 | C35: I | D35: BA21-OS-TOPS-ST-600107-001-EN | E35: BA21-OS-TOPS-ST-706412-001-EN | F35: #BAL.BA21=212&TC030-706412-001-EN | G35: Topside - Upper Grillage - Pri. Steel -Block A1 Sub Assembly SA07_Sheet.001 | H35: 47359 | I35: PRI. STEEL | J35: A1 | K35: Deck & Section | L35: FABRICATION | M35: PREFAB | N35: BA11-OS-TOPS-ST-300214-EN | O35: Topside Upper Grillage Arrangement | P35: 45898 | Q35: Submitted | R35: 45910 | V35: R1 | X35: Sent in TR_DRW_GRI_BA2_DOSA_001 | Y35: 45898
B36: 23 | C36: I | D36: BA21-OS-TOPS-ST-600107-002-EN | E36: BA21-OS-TOPS-ST-706412-002-EN | F36: #BAL.BA21=212&TC030-706412-002-EN | G36: Topside - Upper Grillage - Pri. Steel -Block A1 Sub Assembly SA07_Sheet.002 | H36: 47359 | I36: PRI. STEEL | J36: A1 | K36: Deck & Section | L36: FABRICATION | M36: PREFAB | N36: BA11-OS-TOPS-ST-300214-EN | O36: Topside Upper Grillage Arrangement | P36: 45898 | Q36: Submitted | R36: 45910 | V36: R1 | X36: Sent in TR_DRW_GRI_BA2_DOSA_001 | Y36: 45898
B37: 24 | C37: I | D37: BA21-OS-TOPS-ST-600107-003-EN | E37: BA21-OS-TOPS-ST-706412-003-EN | F37: #BAL.BA21=212&TC030-706412-003-EN | G37: Topside - Upper Grillage - Pri. Steel -Block A1 Sub Assembly SA07_Sheet.003 | H37: 47359 | I37: PRI. STEEL | J37: A1 | K37: Deck & Section | L37: FABRICATION | M37: PREFAB | N37: BA11-OS-TOPS-ST-300214-EN | O37: Topside Upper Grillage Arrangement | P37: 45898 | Q37: Submitted | R37: 45910 | V37: R1 | X37: Sent in TR_DRW_GRI_BA2_DOSA_001 | Y37: 45898
B38: 25 | C38: I | D38: BA21-OS-TOPS-ST-600107-004-EN | E38: BA21-OS-TOPS-ST-706412-004-EN | F38: #BAL.BA21=212&TC030-706412-004-EN | G38: Topside - Upper Grillage - Pri. Steel -Block A1 Sub Assembly SA07_Sheet.004 | H38: 47359 | I38: PRI. STEEL | J38: A1 | K38: Deck & Section | L38: FABRICATION | M38: PREFAB | N38: BA11-OS-TOPS-ST-300214-EN | O38: Topside Upper Grillage Arrangement | P38: 45898 | Q38: Submitted | R38: 45910 | V38: R1 | X38: Sent in TR_DRW_GRI_BA2_DOSA_001 | Y38: 45898
A39: 9 | B39: 26 | C39: I | D39: BA21-OS-TOPS-ST-600108-EN | E39: BA21-OS-TOPS-ST-706413-EN | F39: #BAL.BA21=212&TC030-706413-EN | G39: Topside - Upper Grillage - Pri. Steel -Block A1 Sub Assembly SP01 | H39: 47359 | I39: PRI. STEEL | J39: A1 | K39: Deck & Section | L39: FABRICATION | M39: PREFAB | N39: BA11-OS-TOPS-ST-300214-EN | O39: Topside Upper Grillage Arrangement | P39: 45898 | Q39: Submitted | R39: 45910 | V39: R1 | W39: Submitted | X39: Sent in TR_DRW_GRI_BA2_DOSA_001 | Y39: 45898
B40: 26 | C40: I | D40: BA21-OS-TOPS-ST-600108-001-EN | E40: BA21-OS-TOPS-ST-706413-001-EN | F40: #BAL.BA21=212&TC030-706413-001-EN | G40: Topside - Upper Grillage - Pri. Steel -Block A1 Sub Assembly SP01_Sheet.001 | H40: 47359 | I40: PRI. STEEL | J40: A1 | K40: Deck & Section | L40: FABRICATION | M40: PREFAB | N40: BA11-OS-TOPS-ST-300214-EN | O40: Topside Upper Grillage Arrangement | P40: 45898 | Q40: Submitted | R40: 45910 | V40: R1 | X40: Sent in TR_DRW_GRI_BA2_DOSA_001 | Y40: 45898
B41: 27 | C41: I | D41: BA21-OS-TOPS-ST-600108-002-EN | E41: BA21-OS-TOPS-ST-706413-002-EN | F41: #BAL.BA21=212&TC030-706413-002-EN | G41: Topside - Upper Grillage - Pri. Steel -Block A1 Sub Assembly SP01_Sheet.002 | H41: 47359 | I41: PRI. STEEL | J41: A1 | K41: Deck & Section | L41: FABRICATION | M41: PREFAB | N41: BA11-OS-TOPS-ST-300214-EN | O41: Topside Upper Grillage Arrangement | P41: 45898 | Q41: Submitted | R41: 45910 | V41: R1 | X41: Sent in TR_DRW_GRI_BA2_DOSA_001 | Y41: 45898
...

Sheet KPIs
L1: Documentation Status Balwin2 Upper Grillage
B2: Drawing Status Balwin2 Upper Grillage
B3: Drawings Clasification | C3: Total number of documents | D3: Not submitted yet | E3: R1 Submitted under Review | F3: Code 1 | G3: Code 2 | H3: Code 3
B4: 1. A Block | C4: =COUNTIFS('Drawing List TWP'!A8:A145,"<>") -> 18 | D4: =C4-(E4+F4+G4+H4) -> 0 | E4: =COUNTIFS('Drawing List TWP'!W8:W145,"Sub*") -> 18 | F4: =COUNTIFS('Drawing List TWP'!W9:W113,"Code 1") -> 0 | G4: =COUNTIFS('Drawing List TWP'!W9:W113,"Code 2") -> 0 | H4: =COUNTIFS('Drawing List TWP'!W9:W113,"Code 3") -> 0
B5: 2. B Block | C5: =COUNTIFS('Drawing List TWP'!A147:A254,"<>") -> 14 | D5: =C5-(E5+F5+G5+H5) -> 0 | E5: =COUNTIFS('Drawing List TWP'!W147:W254,"Sub*") -> 14 | F5: =COUNTIFS('Drawing List TWP'!W148:W232,"Code 1") -> 0 | G5: =COUNTIFS('Drawing List TWP'!W148:W232,"Code 2") -> 0 | H5: =COUNTIFS('Drawing List TWP'!W148:W232,"Code 3") -> 0
B6: 3. C Block | C6: =COUNTIFS('Drawing List TWP'!A260:A361,"<>") -> 14 | D6: =C6-(E6+F6+G6+H6) -> 0 | E6: =COUNTIFS('Drawing List TWP'!W260:W361,"Sub*") -> 14 | F6: =COUNTIFS('Drawing List TWP'!W261:W338,"Code 1") -> 0 | G6: =COUNTIFS('Drawing List TWP'!W261:W338,"Code 2") -> 0 | H6: =COUNTIFS('Drawing List TWP'!W261:W338,"Code 3") -> 0
B7: 4. D Block | C7: =COUNTIFS('Drawing List TWP'!A363:A502,"<>") -> 18 | D7: =C7-(E7+F7+G7+H7) -> 0 | E7: =COUNTIFS('Drawing List TWP'!W363:W502,"Sub*") -> 18 | F7: =COUNTIFS('Drawing List TWP'!W364:W470,"Code 1") -> 0 | G7: =COUNTIFS('Drawing List TWP'!W364:W470,"Code 2") -> 0 | H7: =COUNTIFS('Drawing List TWP'!W364:W470,"Code 3") -> 0
B8: 5. E Block | C8: =COUNTIFS('Drawing List TWP'!A504:A531,"<>") -> 6 | D8: =C8-(E8+F8+G8+H8) -> 0 | E8: =COUNTIFS('Drawing List TWP'!W504:W531,"Sub*") -> 6 | F8: =COUNTIFS('Drawing List TWP'!W505:W526,"Code 1") -> 0 | G8: =COUNTIFS('Drawing List TWP'!W505:W526,"Code 2") -> 0 | H8: =COUNTIFS('Drawing List TWP'!W505:W526,"Code 3") -> 0
B9: 6. Nesting | C9: 5 | D9: =C9-(E9+F9+G9+H9) -> 0 | E9: =COUNTIFS('Drawing List TWP'!W7,"Sub*")+COUNTIFS('Drawing List TWP'!W146,"Sub*")+COUNTIFS('Drawing List TWP'!W259,"Sub*")+COUNTIFS('Drawing List TWP'!W362,"Sub*")+COUNTIFS('Drawing List TWP'!W503,"Sub*") -> 5 | F9: =COUNTIFS('Drawing List TWP'!W15:W152,"Code 1") -> 0 | G9: =COUNTIFS('Drawing List TWP'!W15:W152,"Code 2") -> 0 | H9: =COUNTIFS('Drawing List TWP'!W15:W152,"Code 3") -> 0
B10: Total | C10: =SUM(C4:C9) -> 75 | D10: =SUM(D4:D7) -> 0 | E10: =SUM(E4:E9) -> 75 | F10: =SUM(F4:F7) -> 0 | G10: =SUM(G4:G7) -> 0 | H10: =SUM(H4:H7) -> 0
B14: Drawing Progress Balwin2 Upper Grillage
B15: Drawings Clasification | C15: Total number of documents | D15: Not submitted yet | E15: R1 Submitted | F15: R2* On going | G15: Code 1 | H15: Code 2 | I15: Code 3
B16: 1. A Block | C16: =C4 -> 18 | D16: 0 | E16: 1 | F16: 0.9 | G16: =COUNTIFS('Drawing List TWP'!W24:W162,"Code 1") -> 0 | H16: =COUNTIFS('Drawing List TWP'!W24:W162,"Code 2") -> 0 | I16: =COUNTIFS('Drawing List TWP'!W24:W162,"Code 3") -> 0
B17: 2. B Block | C17: =C5 -> 14 | D17: 0 | E17: 1 | F17: 0.9 | G17: =COUNTIFS('Drawing List TWP'!W164:W273,"Code 1") -> 0 | H17: =COUNTIFS('Drawing List TWP'!W164:W273,"Code 2") -> 0 | I17: =COUNTIFS('Drawing List TWP'!W164:W273,"Code 3") -> 0
B18: 3. C Block | C18: =C6 -> 14 | D18: 0 | E18: 1 | F18: 0.9 | G18: =COUNTIFS('Drawing List TWP'!W276:W376,"Code 1") -> 0 | H18: =COUNTIFS('Drawing List TWP'!W276:W376,"Code 2") -> 0 | I18: =COUNTIFS('Drawing List TWP'!W276:W376,"Code 3") -> 0
B19: 4. D Block | C19: =C7 -> 18 | D19: 0 | E19: 1 | F19: 0.9 | G19: =COUNTIFS('Drawing List TWP'!W379:W523,"Code 1") -> 0 | H19: =COUNTIFS('Drawing List TWP'!W379:W523,"Code 2") -> 0 | I19: =COUNTIFS('Drawing List TWP'!W379:W523,"Code 3") -> 0
B20: 5. E Block | C20: =C8 -> 6 | D20: 0 | E20: 1 | F20: 0.9 | G20: =COUNTIFS('Drawing List TWP'!W525:W526,"Code 1") -> 0 | H20: =COUNTIFS('Drawing List TWP'!W525:W526,"Code 2") -> 0 | I20: =COUNTIFS('Drawing List TWP'!W525:W526,"Code 3") -> 0
B21: 6. Nesting | C21: =C9 -> 5 | D21: 0 | E21: 1 | F21: 0.9 | G21: =COUNTIFS('Drawing List TWP'!W30:W168,"Code 1") -> 0 | H21: =COUNTIFS('Drawing List TWP'!W30:W168,"Code 2") -> 0 | I21: =COUNTIFS('Drawing List TWP'!W30:W168,"Code 3") -> 0
B22: Total | C22: =SUM(C16:C21) -> 75 | D22: 0 | E22: 1 | F22: 0.9 | G22: =SUM(G16:G19) -> 0 | H22: =SUM(H16:H19) -> 0 | I22: =SUM(I16:I19) -> 0

Sheet Data Validation
B3: CODE 1 | C3: Approved
B4: CODE 2 | C4: Approved with Comments
B5: CODE 3 | C5: Not Approved
B6: Sub
B7: Commented
B8: LEMS comment
B9: -
B15: AFC
B16: Commented
B17: Issued
B18: -
